Workbook

Sheet Paramètres_Equipe
A1: Liste des Collaborateurs
A2: Martin Dupont
A3: Julie Durand
A4: Luc Lefebvre
A5: Sophie Martin
A6: Thomas Petit
A7: Fin de liste des collaborateurs

Sheet Janvier_2026
A1: Date | B1: Période | C1: Martin Dupont | D1: Julie Durand | E1: Luc Lefebvre | F1: Sophie Martin | G1: Thomas Petit
A2: 46023 | B2: Matin
B3: Après-midi
A4: 46024 | B4: Matin
B5: Après-midi
A6: 46025 | B6: Matin
B7: Après-midi
A8: 46026 | B8: Matin
B9: Après-midi
A10: 46027 | B10: Matin
B11: Après-midi
A12: 46028 | B12: Matin
B13: Après-midi
A14: 46029 | B14: Matin
B15: Après-midi
A16: 46030 | B16: Matin
B17: Après-midi
A18: 46031 | B18: Matin
B19: Après-midi
A20: 46032 | B20: Matin
B21: Après-midi
A22: 46033 | B22: Matin
B23: Après-midi
A24: 46034 | B24: Matin
B25: Après-midi
A26: 46035 | B26: Matin
B27: Après-midi
A28: 46036 | B28: Matin
B29: Après-midi
A30: 46037 | B30: Matin
B31: Après-midi
A32: 46038 | B32: Matin
B33: Après-midi
A34: 46039 | B34: Matin
B35: Après-midi
A36: 46040 | B36: Matin
B37: Après-midi
A38: 46041 | B38: Matin
B39: Après-midi
A40: 46042 | B40: Matin
...

Sheet Février_2026
A1: Date | B1: Période | C1: Martin Dupont | D1: Julie Durand | E1: Luc Lefebvre | F1: Sophie Martin | G1: Thomas Petit
A2: 46054 | B2: Matin
B3: Après-midi
A4: 46055 | B4: Matin
B5: Après-midi
A6: 46056 | B6: Matin
B7: Après-midi
A8: 46057 | B8: Matin
B9: Après-midi
A10: 46058 | B10: Matin
B11: Après-midi
A12: 46059 | B12: Matin
B13: Après-midi
A14: 46060 | B14: Matin
B15: Après-midi
A16: 46061 | B16: Matin
B17: Après-midi
A18: 46062 | B18: Matin
B19: Après-midi
A20: 46063 | B20: Matin
B21: Après-midi
A22: 46064 | B22: Matin
B23: Après-midi
A24: 46065 | B24: Matin
B25: Après-midi
A26: 46066 | B26: Matin
B27: Après-midi
A28: 46067 | B28: Matin
B29: Après-midi
A30: 46068 | B30: Matin
B31: Après-midi
A32: 46069 | B32: Matin
B33: Après-midi
A34: 46070 | B34: Matin
B35: Après-midi
A36: 46071 | B36: Matin
B37: Après-midi
A38: 46072 | B38: Matin
B39: Après-midi
A40: 46073 | B40: Matin
...

Sheet Mars_2026
A1: Date | B1: Période | C1: Martin Dupont | D1: Julie Durand | E1: Luc Lefebvre | F1: Sophie Martin | G1: Thomas Petit
A2: 46082 | B2: Matin
B3: Après-midi
A4: 46083 | B4: Matin
B5: Après-midi
A6: 46084 | B6: Matin
B7: Après-midi
A8: 46085 | B8: Matin
B9: Après-midi
A10: 46086 | B10: Matin
B11: Après-midi
A12: 46087 | B12: Matin
B13: Après-midi
A14: 46088 | B14: Matin
B15: Après-midi
A16: 46089 | B16: Matin
B17: Après-midi
A18: 46090 | B18: Matin
B19: Après-midi
A20: 46091 | B20: Matin
B21: Après-midi
A22: 46092 | B22: Matin
B23: Après-midi
A24: 46093 | B24: Matin
B25: Après-midi
A26: 46094 | B26: Matin
B27: Après-midi
A28: 46095 | B28: Matin
B29: Après-midi
A30: 46096 | B30: Matin
B31: Après-midi
A32: 46097 | B32: Matin
B33: Après-midi
A34: 46098 | B34: Matin
B35: Après-midi
A36: 46099 | B36: Matin
B37: Après-midi
A38: 46100 | B38: Matin
B39: Après-midi
A40: 46101 | B40: Matin
...

Sheet Avril_2026
A1: Date | B1: Période | C1: Martin Dupont | D1: Julie Durand | E1: Luc Lefebvre | F1: Sophie Martin | G1: Thomas Petit
A2: 46113 | B2: Matin
B3: Après-midi
A4: 46114 | B4: Matin
B5: Après-midi
A6: 46115 | B6: Matin
B7: Après-midi
A8: 46116 | B8: Matin
B9: Après-midi
A10: 46117 | B10: Matin
B11: Après-midi
A12: 46118 | B12: Matin
B13: Après-midi
A14: 46119 | B14: Matin
B15: Après-midi
A16: 46120 | B16: Matin
B17: Après-midi
A18: 46121 | B18: Matin
B19: Après-midi
A20: 46122 | B20: Matin
B21: Après-midi
A22: 46123 | B22: Matin
B23: Après-midi
A24: 46124 | B24: Matin
B25: Après-midi
A26: 46125 | B26: Matin
B27: Après-midi
A28: 46126 | B28: Matin
B29: Après-midi
A30: 46127 | B30: Matin
B31: Après-midi
A32: 46128 | B32: Matin
B33: Après-midi
A34: 46129 | B34: Matin
B35: Après-midi
A36: 46130 | B36: Matin
B37: Après-midi
A38: 46131 | B38: Matin
B39: Après-midi
A40: 46132 | B40: Matin
...

Sheet Mai_2026
A1: Date | B1: Période | C1: Martin Dupont | D1: Julie Durand | E1: Luc Lefebvre | F1: Sophie Martin | G1: Thomas Petit
A2: 46143 | B2: Matin
B3: Après-midi
A4: 46144 | B4: Matin
B5: Après-midi
A6: 46145 | B6: Matin
B7: Après-midi
A8: 46146 | B8: Matin
B9: Après-midi
A10: 46147 | B10: Matin
B11: Après-midi
A12: 46148 | B12: Matin
B13: Après-midi
A14: 46149 | B14: Matin
B15: Après-midi
A16: 46150 | B16: Matin
B17: Après-midi
A18: 46151 | B18: Matin
B19: Après-midi
A20: 46152 | B20: Matin
B21: Après-midi
A22: 46153 | B22: Matin
B23: Après-midi
A24: 46154 | B24: Matin
B25: Après-midi
A26: 46155 | B26: Matin
B27: Après-midi
A28: 46156 | B28: Matin
B29: Après-midi
A30: 46157 | B30: Matin
B31: Après-midi
A32: 46158 | B32: Matin
B33: Après-midi
A34: 46159 | B34: Matin
B35: Après-midi
A36: 46160 | B36: Matin
B37: Après-midi
A38: 46161 | B38: Matin
B39: Après-midi
A40: 46162 | B40: Matin
...

Sheet Juin_2026
A1: Date | B1: Période | C1: Martin Dupont | D1: Julie Durand | E1: Luc Lefebvre | F1: Sophie Martin | G1: Thomas Petit
A2: 46174 | B2: Matin
B3: Après-midi
A4: 46175 | B4: Matin
B5: Après-midi
A6: 46176 | B6: Matin
B7: Après-midi
A8: 46177 | B8: Matin
B9: Après-midi
A10: 46178 | B10: Matin
B11: Après-midi
A12: 46179 | B12: Matin
B13: Après-midi
A14: 46180 | B14: Matin
B15: Après-midi
A16: 46181 | B16: Matin
B17: Après-midi
A18: 46182 | B18: Matin
B19: Après-midi
A20: 46183 | B20: Matin
B21: Après-midi
A22: 46184 | B22: Matin
B23: Après-midi
A24: 46185 | B24: Matin
B25: Après-midi
A26: 46186 | B26: Matin
B27: Après-midi
A28: 46187 | B28: Matin
B29: Après-midi
A30: 46188 | B30: Matin
B31: Après-midi
A32: 46189 | B32: Matin
B33: Après-midi
A34: 46190 | B34: Matin
B35: Après-midi
A36: 46191 | B36: Matin
B37: Après-midi
A38: 46192 | B38: Matin
B39: Après-midi
A40: 46193 | B40: Matin
...

Sheet Juillet_2026
A1: Date | B1: Période | C1: Martin Dupont | D1: Julie Durand | E1: Luc Lefebvre | F1: Sophie Martin | G1: Thomas Petit
A2: 46204 | B2: Matin
B3: Après-midi
A4: 46205 | B4: Matin
B5: Après-midi
A6: 46206 | B6: Matin
B7: Après-midi
A8: 46207 | B8: Matin
B9: Après-midi
A10: 46208 | B10: Matin
B11: Après-midi
A12: 46209 | B12: Matin
B13: Après-midi
A14: 46210 | B14: Matin
B15: Après-midi
A16: 46211 | B16: Matin
B17: Après-midi
A18: 46212 | B18: Matin
B19: Après-midi
A20: 46213 | B20: Matin
B21: Après-midi
A22: 46214 | B22: Matin
B23: Après-midi
A24: 46215 | B24: Matin
B25: Après-midi
A26: 46216 | B26: Matin
B27: Après-midi
A28: 46217 | B28: Matin
B29: Après-midi
A30: 46218 | B30: Matin
B31: Après-midi
A32: 46219 | B32: Matin
B33: Après-midi
A34: 46220 | B34: Matin
B35: Après-midi
A36: 46221 | B36: Matin
B37: Après-midi
A38: 46222 | B38: Matin
B39: Après-midi
A40: 46223 | B40: Matin
...

Sheet Août_2026
A1: Date | B1: Période | C1: Martin Dupont | D1: Julie Durand | E1: Luc Lefebvre | F1: Sophie Martin | G1: Thomas Petit
A2: 46235 | B2: Matin
B3: Après-midi
A4: 46236 | B4: Matin
B5: Après-midi
A6: 46237 | B6: Matin
B7: Après-midi
A8: 46238 | B8: Matin
B9: Après-midi
A10: 46239 | B10: Matin
B11: Après-midi
A12: 46240 | B12: Matin
B13: Après-midi
A14: 46241 | B14: Matin
B15: Après-midi
A16: 46242 | B16: Matin
B17: Après-midi
A18: 46243 | B18: Matin
B19: Après-midi
A20: 46244 | B20: Matin
B21: Après-midi
A22: 46245 | B22: Matin
B23: Après-midi
A24: 46246 | B24: Matin
B25: Après-midi
A26: 46247 | B26: Matin
B27: Après-midi
A28: 46248 | B28: Matin
B29: Après-midi
A30: 46249 | B30: Matin
B31: Après-midi
A32: 46250 | B32: Matin
B33: Après-midi
A34: 46251 | B34: Matin
B35: Après-midi
A36: 46252 | B36: Matin
B37: Après-midi
A38: 46253 | B38: Matin
B39: Après-midi
A40: 46254 | B40: Matin
...

Sheet Septembre_2026
A1: Date | B1: Période | C1: Martin Dupont | D1: Julie Durand | E1: Luc Lefebvre | F1: Sophie Martin | G1: Thomas Petit
A2: 46266 | B2: Matin
B3: Après-midi
A4: 46267 | B4: Matin
B5: Après-midi
A6: 46268 | B6: Matin
B7: Après-midi
A8: 46269 | B8: Matin
B9: Après-midi
A10: 46270 | B10: Matin
B11: Après-midi
A12: 46271 | B12: Matin
B13: Après-midi
A14: 46272 | B14: Matin
B15: Après-midi
A16: 46273 | B16: Matin
B17: Après-midi
A18: 46274 | B18: Matin
B19: Après-midi
A20: 46275 | B20: Matin
B21: Après-midi
A22: 46276 | B22: Matin
B23: Après-midi
A24: 46277 | B24: Matin
B25: Après-midi
A26: 46278 | B26: Matin
B27: Après-midi
A28: 46279 | B28: Matin
B29: Après-midi
A30: 46280 | B30: Matin
B31: Après-midi
A32: 46281 | B32: Matin
B33: Après-midi
A34: 46282 | B34: Matin
B35: Après-midi
A36: 46283 | B36: Matin
B37: Après-midi
A38: 46284 | B38: Matin
B39: Après-midi
A40: 46285 | B40: Matin
...

Sheet Octobre_2026
A1: Date | B1: Période | C1: Martin Dupont | D1: Julie Durand | E1: Luc Lefebvre | F1: Sophie Martin | G1: Thomas Petit
A2: 46296 | B2: Matin
B3: Après-midi
A4: 46297 | B4: Matin
B5: Après-midi
A6: 46298 | B6: Matin
B7: Après-midi
A8: 46299 | B8: Matin
B9: Après-midi
A10: 46300 | B10: Matin
B11: Après-midi
A12: 46301 | B12: Matin
B13: Après-midi
A14: 46302 | B14: Matin
B15: Après-midi
A16: 46303 | B16: Matin
B17: Après-midi
A18: 46304 | B18: Matin
B19: Après-midi
A20: 46305 | B20: Matin
B21: Après-midi
A22: 46306 | B22: Matin
B23: Après-midi
A24: 46307 | B24: Matin
B25: Après-midi
A26: 46308 | B26: Matin
B27: Après-midi
A28: 46309 | B28: Matin
B29: Après-midi
A30: 46310 | B30: Matin
B31: Après-midi
A32: 46311 | B32: Matin
B33: Après-midi
A34: 46312 | B34: Matin
B35: Après-midi
A36: 46313 | B36: Matin
B37: Après-midi
A38: 46314 | B38: Matin
B39: Après-midi
A40: 46315 | B40: Matin
...

Sheet Novembre_2026
A1: Date | B1: Période | C1: Martin Dupont | D1: Julie Durand | E1: Luc Lefebvre | F1: Sophie Martin | G1: Thomas Petit
A2: 46327 | B2: Matin
B3: Après-midi
A4: 46328 | B4: Matin
B5: Après-midi
A6: 46329 | B6: Matin
B7: Après-midi
A8: 46330 | B8: Matin
B9: Après-midi
A10: 46331 | B10: Matin
B11: Après-midi
A12: 46332 | B12: Matin
B13: Après-midi
A14: 46333 | B14: Matin
B15: Après-midi
A16: 46334 | B16: Matin
B17: Après-midi
A18: 46335 | B18: Matin
B19: Après-midi
A20: 46336 | B20: Matin
B21: Après-midi
A22: 46337 | B22: Matin
B23: Après-midi
A24: 46338 | B24: Matin
B25: Après-midi
A26: 46339 | B26: Matin
B27: Après-midi
A28: 46340 | B28: Matin
B29: Après-midi
A30: 46341 | B30: Matin
B31: Après-midi
A32: 46342 | B32: Matin
B33: Après-midi
A34: 46343 | B34: Matin
B35: Après-midi
A36: 46344 | B36: Matin
B37: Après-midi
A38: 46345 | B38: Matin
B39: Après-midi
A40: 46346 | B40: Matin
...

Sheet Décembre_2026
A1: Date | B1: Période | C1: Martin Dupont | D1: Julie Durand | E1: Luc Lefebvre | F1: Sophie Martin | G1: Thomas Petit
A2: 46357 | B2: Matin
B3: Après-midi
A4: 46358 | B4: Matin
B5: Après-midi
A6: 46359 | B6: Matin
B7: Après-midi
A8: 46360 | B8: Matin
B9: Après-midi
A10: 46361 | B10: Matin
B11: Après-midi
A12: 46362 | B12: Matin
B13: Après-midi
A14: 46363 | B14: Matin
B15: Après-midi
A16: 46364 | B16: Matin
B17: Après-midi
A18: 46365 | B18: Matin
B19: Après-midi
A20: 46366 | B20: Matin
B21: Après-midi
A22: 46367 | B22: Matin
B23: Après-midi
A24: 46368 | B24: Matin
B25: Après-midi
A26: 46369 | B26: Matin
B27: Après-midi
A28: 46370 | B28: Matin
B29: Après-midi
A30: 46371 | B30: Matin
B31: Après-midi
A32: 46372 | B32: Matin
B33: Après-midi
A34: 46373 | B34: Matin
B35: Après-midi
A36: 46374 | B36: Matin
B37: Après-midi
A38: 46375 | B38: Matin
B39: Après-midi
A40: 46376 | B40: Matin
...

Sheet Bilan année
A1: Membre | B1: Janvier | C1: Février | D1: Mars | E1: Avril | F1: Mai | G1: Juin | H1: Juillet | I1: Août | J1: Septembre | K1: Octobre | L1: Novembre | M1: Décembre | N1: TOTAL
A2: Martin Dupont | B2: ='Janvier_2026'!C64 | C2: ='Février_2026'!C58 | D2: ='Mars_2026'!C64 | E2: ='Avril_2026'!C62 | F2: ='Mai_2026'!C64 | G2: ='Juin_2026'!C62 | H2: ='Juillet_2026'!C64 | I2: ='Août_2026'!C64 | J2: ='Septembre_2026'!C62 | K2: ='Octobre_2026'!C64 | L2: ='Novembre_2026'!C62 | M2: ='Décembre_2026'!C64 | N2: =SUM(B2:M2)
A3: Julie Durand | B3: ='Janvier_2026'!D64 | C3: ='Février_2026'!D58 | D3: ='Mars_2026'!D64 | E3: ='Avril_2026'!D62 | F3: ='Mai_2026'!D64 | G3: ='Juin_2026'!D62 | H3: ='Juillet_2026'!D64 | I3: ='Août_2026'!D64 | J3: ='Septembre_2026'!D62 | K3: ='Octobre_2026'!D64 | L3: ='Novembre_2026'!D62 | M3: ='Décembre_2026'!D64 | N3: =SUM(B3:M3)
A4: Luc Lefebvre | B4: ='Janvier_2026'!E64 | C4: ='Février_2026'!E58 | D4: ='Mars_2026'!E64 | E4: ='Avril_2026'!E62 | F4: ='Mai_2026'!E64 | G4: ='Juin_2026'!E62 | H4: ='Juillet_2026'!E64 | I4: ='Août_2026'!E64 | J4: ='Septembre_2026'!E62 | K4: ='Octobre_2026'!E64 | L4: ='Novembre_2026'!E62 | M4: ='Décembre_2026'!E64 | N4: =SUM(B4:M4)
A5: Sophie Martin | B5: ='Janvier_2026'!F64 | C5: ='Février_2026'!F58 | D5: ='Mars_2026'!F64 | E5: ='Avril_2026'!F62 | F5: ='Mai_2026'!F64 | G5: ='Juin_2026'!F62 | H5: ='Juillet_2026'!F64 | I5: ='Août_2026'!F64 | J5: ='Septembre_2026'!F62 | K5: ='Octobre_2026'!F64 | L5: ='Novembre_2026'!F62 | M5: ='Décembre_2026'!F64 | N5: =SUM(B5:M5)
A6: Thomas Petit | B6: ='Janvier_2026'!G64 | C6: ='Février_2026'!G58 | D6: ='Mars_2026'!G64 | E6: ='Avril_2026'!G62 | F6: ='Mai_2026'!G64 | G6: ='Juin_2026'!G62 | H6: ='Juillet_2026'!G64 | I6: ='Août_2026'!G64 | J6: ='Septembre_2026'!G62 | K6: ='Octobre_2026'!G64 | L6: ='Novembre_2026'!G62 | M6: ='Décembre_2026'!G64 | N6: =SUM(B6:M6)
